[0.014s] Traceback (most recent call last):
  File "/home/ubuntu/.local/lib/python3.8/site-packages/colcon_core/executor/__init__.py", line 91, in __call__
    rc = await self.task(*args, **kwargs)
  File "/home/ubuntu/.local/lib/python3.8/site-packages/colcon_core/task/__init__.py", line 93, in __call__
    return await task_method(*args, **kwargs)
  File "/home/ubuntu/.local/lib/python3.8/site-packages/colcon_cmake/task/cmake/build.py", line 87, in build
    rc = await self._reconfigure(args, env)
  File "/home/ubuntu/.local/lib/python3.8/site-packages/colcon_cmake/task/cmake/build.py", line 169, in _reconfigure
    raise RuntimeError("Could not find 'cmake' executable")
RuntimeError: Could not find 'cmake' executable
